Workbook

Sheet NOW
A1: ▸ | B1: Run 1 | C1: hickman-ff | E1: ▸ | F1: Run 2 | G1: simonson-thor
A2: {=IFERROR(_xlfn.XLOOKUP($C$1, Runs[Run ID], Runs[Title]), "— pick a run —") & " (" & IFERROR(_xlfn.XLOOKUP($C$1, Runs[Run ID], Runs[Track]), "— pick a run —") & ")"} -> Hickman's Fantastic Four / FF (Hickman Saga) | E2: {=IFERROR(_xlfn.XLOOKUP($G$1, Runs[Run ID], Runs[Title]), "— pick a run —") & " (" & IFERROR(_xlfn.XLOOKUP($G$1, Runs[Run ID], Runs[Track]), "— pick a run —") & ")"} -> Simonson's Thor (Thor)
A4: Progress | C4: =IF(COUNTIF(Reading_Order[Run ID],$C$1)=0,"",REPT("▰",ROUND((1-$C$5/COUNTIF(Reading_Order[Run ID],$C$1))*10,0))&REPT("▱",10-ROUND((1-$C$5/COUNTIF(Reading_Order[Run ID],$C$1))*10,0))&" "&TEXT(1-$C$5/COUNTIF(Reading_Order[Run ID],$C$1),"0%")) -> ▰▰▰▰▰▱▱▱▱▱ 46% | E4: Progress | G4: =IF(COUNTIF(Reading_Order[Run ID],$G$1)=0,"",REPT("▰",ROUND((1-$G$5/COUNTIF(Reading_Order[Run ID],$G$1))*10,0))&REPT("▱",10-ROUND((1-$G$5/COUNTIF(Reading_Order[Run ID],$G$1))*10,0))&" "&TEXT(1-$G$5/COUNTIF(Reading_Order[Run ID],$G$1),"0%")) -> ▰▰▰▱▱▱▱▱▱▱ 34%
A5: Left | C5: =COUNTIFS(Reading_Order[Run ID],$C$1,Reading_Order[Completed],FALSE) -> 33 | E5: Left | G5: =COUNTIFS(Reading_Order[Run ID],$G$1,Reading_Order[Completed],FALSE) -> 33
A6: Est. done | C6: =IF($C$5=0, "✓ complete", TEXT(TODAY()+$C$5, "d mmm yyyy")) -> 31 Oct 2026 | E6: Est. done | G6: =IF($G$5=0, "✓ complete", TEXT(TODAY()+$G$5, "d mmm yyyy")) -> 31 Oct 2026
A7: Next up | C7: =IFERROR(__xludf.DUMMYFUNCTION("IFERROR(INDEX(SORT(FILTER(Reading_Order[Issue],Reading_Order[Run ID]=$C$1,Reading_Order[Completed]=FALSE),FILTER(Reading_Order[Sequence],Reading_Order[Run ID]=$C$1,Reading_Order[Completed]=FALSE),TRUE),1),""✓ run complete"")"),"FF (2011) #4") -> FF (2011) #4 | E7: Next up | G7: =IFERROR(__xludf.DUMMYFUNCTION("IFERROR(INDEX(SORT(FILTER(Reading_Order[Issue],Reading_Order[Run ID]=$G$1,Reading_Order[Completed]=FALSE),FILTER(Reading_Order[Sequence],Reading_Order[Run ID]=$G$1,Reading_Order[Completed]=FALSE),TRUE),1),""✓ run complete"")"),"Thor #354") -> Thor #354
A9: =IFERROR(__xludf.DUMMYFUNCTION("LET(r, $C$1, t, XLOOKUP(r, Runs[Run ID], Runs[Track]), b, XLOOKUP(r, Runs[Run ID], Runs[Block]), rows, SORT(FILTER(CHOOSECOLS(Runs, 16, 2, 1, 7, 11), (Runs[Track]=t)*(Runs[Block]=b)), 1, 1), HSTACK( MAP(CH"&"OOSECOLS(rows,2), CHOOSECOLS(rows,5), LAMBDA(id, st, IF(id=r, ""▶"", IF(st=""read"", ""✓"", ""·"")))), CHOOSECOLS(rows, 3, 4, 5)))"),"✓") -> ✓ | B9: =IFERROR(__xludf.DUMMYFUNCTION("""COMPUTED_VALUE"""),"Secret Warriors") -> Secret Warriors | C9: =IFERROR(__xludf.DUMMYFUNCTION("""COMPUTED_VALUE"""),31.0) -> 31 | D9: =IFERROR(__xludf.DUMMYFUNCTION("""COMPUTED_VALUE"""),"read") -> read | E9: =IFERROR(__xludf.DUMMYFUNCTION("LET(r, $G$1, t, XLOOKUP(r, Runs[Run ID], Runs[Track]), b, XLOOKUP(r, Runs[Run ID], Runs[Block]), rows, SORT(FILTER(CHOOSECOLS(Runs, 16, 2, 1, 7, 11), (Runs[Track]=t)*(Runs[Block]=b)), 1, 1), HSTACK( MAP(CH"&"OOSECOLS(rows,2), CHOOSECOLS(rows,5), LAMBDA(id, st, IF(id=r, ""▶"", IF(st=""read"", ""✓"", ""·"")))), CHOOSECOLS(rows, 3, 4, 5)))"),"▶") -> ▶ | F9: =IFERROR(__xludf.DUMMYFUNCTION("""COMPUTED_VALUE"""),"Simonson's Thor") -> Simonson's Thor | G9: =IFERROR(__xludf.DUMMYFUNCTION("""COMPUTED_VALUE"""),50.0) -> 50 | H9: =IFERROR(__xludf.DUMMYFUNCTION("""COMPUTED_VALUE"""),"reading") -> reading
A10: =IFERROR(__xludf.DUMMYFUNCTION("""COMPUTED_VALUE"""),"▶") -> ▶ | B10: =IFERROR(__xludf.DUMMYFUNCTION("""COMPUTED_VALUE"""),"Hickman's Fantastic Four / FF") -> Hickman's Fantastic Four / FF | C10: =IFERROR(__xludf.DUMMYFUNCTION("""COMPUTED_VALUE"""),61.0) -> 61 | D10: =IFERROR(__xludf.DUMMYFUNCTION("""COMPUTED_VALUE"""),"reading") -> reading | E10: =IFERROR(__xludf.DUMMYFUNCTION("""COMPUTED_VALUE"""),"·") -> · | F10: =IFERROR(__xludf.DUMMYFUNCTION("""COMPUTED_VALUE"""),"Thor: God of Thunder") -> Thor: God of Thunder | G10: =IFERROR(__xludf.DUMMYFUNCTION("""COMPUTED_VALUE"""),34.0) -> 34 | H10: =IFERROR(__xludf.DUMMYFUNCTION("""COMPUTED_VALUE"""),"unread") -> unread
A11: =IFERROR(__xludf.DUMMYFUNCTION("""COMPUTED_VALUE"""),"·") -> · | B11: =IFERROR(__xludf.DUMMYFUNCTION("""COMPUTED_VALUE"""),"S.H.I.E.L.D.") -> S.H.I.E.L.D. | C11: =IFERROR(__xludf.DUMMYFUNCTION("""COMPUTED_VALUE"""),13.0) -> 13 | D11: =IFERROR(__xludf.DUMMYFUNCTION("""COMPUTED_VALUE"""),"unread") -> unread | E11: =IFERROR(__xludf.DUMMYFUNCTION("""COMPUTED_VALUE"""),"·") -> · | F11: =IFERROR(__xludf.DUMMYFUNCTION("""COMPUTED_VALUE"""),"Original Sin") -> Original Sin | G11: =IFERROR(__xludf.DUMMYFUNCTION("""COMPUTED_VALUE"""),5.0) -> 5 | H11: =IFERROR(__xludf.DUMMYFUNCTION("""COMPUTED_VALUE"""),"unread") -> unread
A12: =IFERROR(__xludf.DUMMYFUNCTION("""COMPUTED_VALUE"""),"·") -> · | B12: =IFERROR(__xludf.DUMMYFUNCTION("""COMPUTED_VALUE"""),"Illuminati Prelude") -> Illuminati Prelude | C12: =IFERROR(__xludf.DUMMYFUNCTION("""COMPUTED_VALUE"""),6.0) -> 6 | D12: =IFERROR(__xludf.DUMMYFUNCTION("""COMPUTED_VALUE"""),"unread") -> unread | E12: =IFERROR(__xludf.DUMMYFUNCTION("""COMPUTED_VALUE"""),"·") -> · | F12: =IFERROR(__xludf.DUMMYFUNCTION("""COMPUTED_VALUE"""),"Aaron's Thor / Mighty Thor") -> Aaron's Thor / Mighty Thor | G12: =IFERROR(__xludf.DUMMYFUNCTION("""COMPUTED_VALUE"""),52.0) -> 52 | H12: =IFERROR(__xludf.DUMMYFUNCTION("""COMPUTED_VALUE"""),"unread") -> unread
A13: =IFERROR(__xludf.DUMMYFUNCTION("""COMPUTED_VALUE"""),"·") -> · | B13: =IFERROR(__xludf.DUMMYFUNCTION("""COMPUTED_VALUE"""),"Ultimate Doomsday") -> Ultimate Doomsday | C13: =IFERROR(__xludf.DUMMYFUNCTION("""COMPUTED_VALUE"""),12.0) -> 12 | D13: =IFERROR(__xludf.DUMMYFUNCTION("""COMPUTED_VALUE"""),"unread") -> unread | E13: =IFERROR(__xludf.DUMMYFUNCTION("""COMPUTED_VALUE"""),"·") -> · | F13: =IFERROR(__xludf.DUMMYFUNCTION("""COMPUTED_VALUE"""),"War of the Realms") -> War of the Realms | G13: =IFERROR(__xludf.DUMMYFUNCTION("""COMPUTED_VALUE"""),36.0) -> 36 | H13: =IFERROR(__xludf.DUMMYFUNCTION("""COMPUTED_VALUE"""),"unread") -> unread
A14: =IFERROR(__xludf.DUMMYFUNCTION("""COMPUTED_VALUE"""),"·") -> · | B14: =IFERROR(__xludf.DUMMYFUNCTION("""COMPUTED_VALUE"""),"Ultimate Comics: Ultimates") -> Ultimate Comics: Ultimates | C14: =IFERROR(__xludf.DUMMYFUNCTION("""COMPUTED_VALUE"""),26.0) -> 26 | D14: =IFERROR(__xludf.DUMMYFUNCTION("""COMPUTED_VALUE"""),"unread") -> unread | E14: =IFERROR(__xludf.DUMMYFUNCTION("""COMPUTED_VALUE"""),"·") -> · | F14: =IFERROR(__xludf.DUMMYFUNCTION("""COMPUTED_VALUE"""),"King Thor") -> King Thor | G14: =IFERROR(__xludf.DUMMYFUNCTION("""COMPUTED_VALUE"""),14.0) -> 14 | H14: =IFERROR(__xludf.DUMMYFUNCTION("""COMPUTED_VALUE"""),"unread") -> unread
A15: =IFERROR(__xludf.DUMMYFUNCTION("""COMPUTED_VALUE"""),"·") -> · | B15: =IFERROR(__xludf.DUMMYFUNCTION("""COMPUTED_VALUE"""),"Hickman's Avengers World") -> Hickman's Avengers World | C15: =IFERROR(__xludf.DUMMYFUNCTION("""COMPUTED_VALUE"""),27.0) -> 27 | D15: =IFERROR(__xludf.DUMMYFUNCTION("""COMPUTED_VALUE"""),"unread") -> unread | E15: =IFERROR(__xludf.DUMMYFUNCTION("""COMPUTED_VALUE"""),"·") -> · | F15: =IFERROR(__xludf.DUMMYFUNCTION("""COMPUTED_VALUE"""),"Cates' Thor") -> Cates' Thor | G15: =IFERROR(__xludf.DUMMYFUNCTION("""COMPUTED_VALUE"""),42.0) -> 42 | H15: =IFERROR(__xludf.DUMMYFUNCTION("""COMPUTED_VALUE"""),"unread") -> unread
A16: =IFERROR(__xludf.DUMMYFUNCTION("""COMPUTED_VALUE"""),"·") -> · | B16: =IFERROR(__xludf.DUMMYFUNCTION("""COMPUTED_VALUE"""),"Infinity") -> Infinity | C16: =IFERROR(__xludf.DUMMYFUNCTION("""COMPUTED_VALUE"""),22.0) -> 22 | D16: =IFERROR(__xludf.DUMMYFUNCTION("""COMPUTED_VALUE"""),"unread") -> unread | E16: =IFERROR(__xludf.DUMMYFUNCTION("""COMPUTED_VALUE"""),"·") -> · | F16: =IFERROR(__xludf.DUMMYFUNCTION("""COMPUTED_VALUE"""),"Immortal Thor") -> Immortal Thor | G16: =IFERROR(__xludf.DUMMYFUNCTION("""COMPUTED_VALUE"""),41.0) -> 41 | H16: =IFERROR(__xludf.DUMMYFUNCTION("""COMPUTED_VALUE"""),"unread") -> unread
A17: =IFERROR(__xludf.DUMMYFUNCTION("""COMPUTED_VALUE"""),"·") -> · | B17: =IFERROR(__xludf.DUMMYFUNCTION("""COMPUTED_VALUE"""),"Hickman's Avengers / New Avengers") -> Hickman's Avengers / New Avengers | C17: =IFERROR(__xludf.DUMMYFUNCTION("""COMPUTED_VALUE"""),57.0) -> 57 | D17: =IFERROR(__xludf.DUMMYFUNCTION("""COMPUTED_VALUE"""),"unread") -> unread
A18: =IFERROR(__xludf.DUMMYFUNCTION("""COMPUTED_VALUE"""),"·") -> · | B18: =IFERROR(__xludf.DUMMYFUNCTION("""COMPUTED_VALUE"""),"Secret Wars (2015)") -> Secret Wars (2015) | C18: =IFERROR(__xludf.DUMMYFUNCTION("""COMPUTED_VALUE"""),16.0) -> 16 | D18: =IFERROR(__xludf.DUMMYFUNCTION("""COMPUTED_VALUE"""),"unread") -> unread
A27: ✓ | B27: ISSUE | E27: ✓ | F27: ISSUE
A28: =IFERROR(__xludf.DUMMYFUNCTION("IFERROR(SORT({FILTER(Reading_Order[Completed],Reading_Order[Run ID]=$C$1),FILTER(Reading_Order[Issue],Reading_Order[Run ID]=$C$1)},FILTER(Reading_Order[Sequence],Reading_Order[Run ID]=$C$1),TRUE),""No issues found for this Run ID"")"),TRUE) -> TRUE | B28: =IFERROR(__xludf.DUMMYFUNCTION("""COMPUTED_VALUE"""),"Dark Reign: Fantastic Four #1") -> Dark Reign: Fantastic Four #1 | E28: =IFERROR(__xludf.DUMMYFUNCTION("IFERROR(SORT({FILTER(Reading_Order[Completed],Reading_Order[Run ID]=$G$1),FILTER(Reading_Order[Issue],Reading_Order[Run ID]=$G$1)},FILTER(Reading_Order[Sequence],Reading_Order[Run ID]=$G$1),TRUE),""No issues found for this Run ID"")"),TRUE) -> TRUE | F28: =IFERROR(__xludf.DUMMYFUNCTION("""COMPUTED_VALUE"""),"Thor #337") -> Thor #337
A29: =IFERROR(__xludf.DUMMYFUNCTION("""COMPUTED_VALUE"""),TRUE) -> TRUE | B29: =IFERROR(__xludf.DUMMYFUNCTION("""COMPUTED_VALUE"""),"Dark Reign: Fantastic Four #2") -> Dark Reign: Fantastic Four #2 | E29: =IFERROR(__xludf.DUMMYFUNCTION("""COMPUTED_VALUE"""),TRUE) -> TRUE | F29: =IFERROR(__xludf.DUMMYFUNCTION("""COMPUTED_VALUE"""),"Thor #338") -> Thor #338
A30: =IFERROR(__xludf.DUMMYFUNCTION("""COMPUTED_VALUE"""),TRUE) -> TRUE | B30: =IFERROR(__xludf.DUMMYFUNCTION("""COMPUTED_VALUE"""),"Dark Reign: Fantastic Four #3") -> Dark Reign: Fantastic Four #3 | E30: =IFERROR(__xludf.DUMMYFUNCTION("""COMPUTED_VALUE"""),TRUE) -> TRUE | F30: =IFERROR(__xludf.DUMMYFUNCTION("""COMPUTED_VALUE"""),"Thor #339") -> Thor #339
A31: =IFERROR(__xludf.DUMMYFUNCTION("""COMPUTED_VALUE"""),TRUE) -> TRUE | B31: =IFERROR(__xludf.DUMMYFUNCTION("""COMPUTED_VALUE"""),"Dark Reign: Fantastic Four #4") -> Dark Reign: Fantastic Four #4 | E31: =IFERROR(__xludf.DUMMYFUNCTION("""COMPUTED_VALUE"""),TRUE) -> TRUE | F31: =IFERROR(__xludf.DUMMYFUNCTION("""COMPUTED_VALUE"""),"Thor #340") -> Thor #340
A32: =IFERROR(__xludf.DUMMYFUNCTION("""COMPUTED_VALUE"""),TRUE) -> TRUE | B32: =IFERROR(__xludf.DUMMYFUNCTION("""COMPUTED_VALUE"""),"Dark Reign: Fantastic Four #5") -> Dark Reign: Fantastic Four #5 | E32: =IFERROR(__xludf.DUMMYFUNCTION("""COMPUTED_VALUE"""),TRUE) -> TRUE | F32: =IFERROR(__xludf.DUMMYFUNCTION("""COMPUTED_VALUE"""),"Thor #341") -> Thor #341
A33: =IFERROR(__xludf.DUMMYFUNCTION("""COMPUTED_VALUE"""),TRUE) -> TRUE | B33: =IFERROR(__xludf.DUMMYFUNCTION("""COMPUTED_VALUE"""),"Dark Reign: The Cabal") -> Dark Reign: The Cabal | E33: =IFERROR(__xludf.DUMMYFUNCTION("""COMPUTED_VALUE"""),TRUE) -> TRUE | F33: =IFERROR(__xludf.DUMMYFUNCTION("""COMPUTED_VALUE"""),"Thor #342") -> Thor #342
A34: =IFERROR(__xludf.DUMMYFUNCTION("""COMPUTED_VALUE"""),TRUE) -> TRUE | B34: =IFERROR(__xludf.DUMMYFUNCTION("""COMPUTED_VALUE"""),"Fantastic Four (1998) #570") -> Fantastic Four (1998) #570 | E34: =IFERROR(__xludf.DUMMYFUNCTION("""COMPUTED_VALUE"""),TRUE) -> TRUE | F34: =IFERROR(__xludf.DUMMYFUNCTION("""COMPUTED_VALUE"""),"Thor #343") -> Thor #343
A35: =IFERROR(__xludf.DUMMYFUNCTION("""COMPUTED_VALUE"""),TRUE) -> TRUE | B35: =IFERROR(__xludf.DUMMYFUNCTION("""COMPUTED_VALUE"""),"Fantastic Four (1998) #571") -> Fantastic Four (1998) #571 | E35: =IFERROR(__xludf.DUMMYFUNCTION("""COMPUTED_VALUE"""),TRUE) -> TRUE | F35: =IFERROR(__xludf.DUMMYFUNCTION("""COMPUTED_VALUE"""),"Thor #344") -> Thor #344
A36: =IFERROR(__xludf.DUMMYFUNCTION("""COMPUTED_VALUE"""),TRUE) -> TRUE | B36: =IFERROR(__xludf.DUMMYFUNCTION("""COMPUTED_VALUE"""),"Fantastic Four (1998) #572") -> Fantastic Four (1998) #572 | E36: =IFERROR(__xludf.DUMMYFUNCTION("""COMPUTED_VALUE"""),TRUE) -> TRUE | F36: =IFERROR(__xludf.DUMMYFUNCTION("""COMPUTED_VALUE"""),"Thor #345") -> Thor #345
A37: =IFERROR(__xludf.DUMMYFUNCTION("""COMPUTED_VALUE"""),TRUE) -> TRUE | B37: =IFERROR(__xludf.DUMMYFUNCTION("""COMPUTED_VALUE"""),"Fantastic Four (1998) #573") -> Fantastic Four (1998) #573 | E37: =IFERROR(__xludf.DUMMYFUNCTION("""COMPUTED_VALUE"""),TRUE) -> TRUE | F37: =IFERROR(__xludf.DUMMYFUNCTION("""COMPUTED_VALUE"""),"Thor #346") -> Thor #346
A38: =IFERROR(__xludf.DUMMYFUNCTION("""COMPUTED_VALUE"""),TRUE) -> TRUE | B38: =IFERROR(__xludf.DUMMYFUNCTION("""COMPUTED_VALUE"""),"Fantastic Four (1998) #574") -> Fantastic Four (1998) #574 | E38: =IFERROR(__xludf.DUMMYFUNCTION("""COMPUTED_VALUE"""),TRUE) -> TRUE | F38: =IFERROR(__xludf.DUMMYFUNCTION("""COMPUTED_VALUE"""),"Thor #347") -> Thor #347
A39: =IFERROR(__xludf.DUMMYFUNCTION("""COMPUTED_VALUE"""),TRUE) -> TRUE | B39: =IFERROR(__xludf.DUMMYFUNCTION("""COMPUTED_VALUE"""),"Fantastic Four (1998) #575") -> Fantastic Four (1998) #575 | E39: =IFERROR(__xludf.DUMMYFUNCTION("""COMPUTED_VALUE"""),TRUE) -> TRUE | F39: =IFERROR(__xludf.DUMMYFUNCTION("""COMPUTED_VALUE"""),"Thor #348") -> Thor #348
A40: =IFERROR(__xludf.DUMMYFUNCTION("""COMPUTED_VALUE"""),TRUE) -> TRUE | B40: =IFERROR(__xludf.DUMMYFUNCTION("""COMPUTED_VALUE"""),"Fantastic Four (1998) #576") -> Fantastic Four (1998) #576 | E40: =IFERROR(__xludf.DUMMYFUNCTION("""COMPUTED_VALUE"""),TRUE) -> TRUE | F40: =IFERROR(__xludf.DUMMYFUNCTION("""COMPUTED_VALUE"""),"Thor #349") -> Thor #349
A41: =IFERROR(__xludf.DUMMYFUNCTION("""COMPUTED_VALUE"""),TRUE) -> TRUE | B41: =IFERROR(__xludf.DUMMYFUNCTION("""COMPUTED_VALUE"""),"Fantastic Four (1998) #577") -> Fantastic Four (1998) #577 | E41: =IFERROR(__xludf.DUMMYFUNCTION("""COMPUTED_VALUE"""),TRUE) -> TRUE | F41: =IFERROR(__xludf.DUMMYFUNCTION("""COMPUTED_VALUE"""),"Thor #350") -> Thor #350
A42: =IFERROR(__xludf.DUMMYFUNCTION("""COMPUTED_VALUE"""),TRUE) -> TRUE | B42: =IFERROR(__xludf.DUMMYFUNCTION("""COMPUTED_VALUE"""),"Fantastic Four (1998) #578") -> Fantastic Four (1998) #578 | E42: =IFERROR(__xludf.DUMMYFUNCTION("""COMPUTED_VALUE"""),TRUE) -> TRUE | F42: =IFERROR(__xludf.DUMMYFUNCTION("""COMPUTED_VALUE"""),"Thor #351") -> Thor #351
A43: =IFERROR(__xludf.DUMMYFUNCTION("""COMPUTED_VALUE"""),TRUE) -> TRUE | B43: =IFERROR(__xludf.DUMMYFUNCTION("""COMPUTED_VALUE"""),"Fantastic Four (1998) #579") -> Fantastic Four (1998) #579 | E43: =IFERROR(__xludf.DUMMYFUNCTION("""COMPUTED_VALUE"""),TRUE) -> TRUE | F43: =IFERROR(__xludf.DUMMYFUNCTION("""COMPUTED_VALUE"""),"Thor #352") -> Thor #352
A44: =IFERROR(__xludf.DUMMYFUNCTION("""COMPUTED_VALUE"""),TRUE) -> TRUE | B44: =IFERROR(__xludf.DUMMYFUNCTION("""COMPUTED_VALUE"""),"Fantastic Four (1998) #580") -> Fantastic Four (1998) #580 | E44: =IFERROR(__xludf.DUMMYFUNCTION("""COMPUTED_VALUE"""),TRUE) -> TRUE | F44: =IFERROR(__xludf.DUMMYFUNCTION("""COMPUTED_VALUE"""),"Thor #353") -> Thor #353
A45: =IFERROR(__xludf.DUMMYFUNCTION("""COMPUTED_VALUE"""),TRUE) -> TRUE | B45: =IFERROR(__xludf.DUMMYFUNCTION("""COMPUTED_VALUE"""),"Fantastic Four (1998) #581") -> Fantastic Four (1998) #581 | E45: =IFERROR(__xludf.DUMMYFUNCTION("""COMPUTED_VALUE"""),FALSE) -> FALSE | F45: =IFERROR(__xludf.DUMMYFUNCTION("""COMPUTED_VALUE"""),"Thor #354") -> Thor #354
A46: =IFERROR(__xludf.DUMMYFUNCTION("""COMPUTED_VALUE"""),TRUE) -> TRUE | B46: =IFERROR(__xludf.DUMMYFUNCTION("""COMPUTED_VALUE"""),"Fantastic Four (1998) #582") -> Fantastic Four (1998) #582 | E46: =IFERROR(__xludf.DUMMYFUNCTION("""COMPUTED_VALUE"""),FALSE) -> FALSE | F46: =IFERROR(__xludf.DUMMYFUNCTION("""COMPUTED_VALUE"""),"Thor #355") -> Thor #355
A47: =IFERROR(__xludf.DUMMYFUNCTION("""COMPUTED_VALUE"""),TRUE) -> TRUE | B47: =IFERROR(__xludf.DUMMYFUNCTION("""COMPUTED_VALUE"""),"Fantastic Four (1998) #583") -> Fantastic Four (1998) #583 | E47: =IFERROR(__xludf.DUMMYFUNCTION("""COMPUTED_VALUE"""),FALSE) -> FALSE | F47: =IFERROR(__xludf.DUMMYFUNCTION("""COMPUTED_VALUE"""),"Thor #356") -> Thor #356
A48: =IFERROR(__xludf.DUMMYFUNCTION("""COMPUTED_VALUE"""),TRUE) -> TRUE | B48: =IFERROR(__xludf.DUMMYFUNCTION("""COMPUTED_VALUE"""),"Fantastic Four (1998) #584") -> Fantastic Four (1998) #584 | E48: =IFERROR(__xludf.DUMMYFUNCTION("""COMPUTED_VALUE"""),FALSE) -> FALSE | F48: =IFERROR(__xludf.DUMMYFUNCTION("""COMPUTED_VALUE"""),"Thor #357") -> Thor #357
A49: =IFERROR(__xludf.DUMMYFUNCTION("""COMPUTED_VALUE"""),TRUE) -> TRUE | B49: =IFERROR(__xludf.DUMMYFUNCTION("""COMPUTED_VALUE"""),"Fantastic Four (1998) #585") -> Fantastic Four (1998) #585 | E49: =IFERROR(__xludf.DUMMYFUNCTION("""COMPUTED_VALUE"""),FALSE) -> FALSE | F49: =IFERROR(__xludf.DUMMYFUNCTION("""COMPUTED_VALUE"""),"Thor #358") -> Thor #358
A50: =IFERROR(__xludf.DUMMYFUNCTION("""COMPUTED_VALUE"""),TRUE) -> TRUE | B50: =IFERROR(__xludf.DUMMYFUNCTION("""COMPUTED_VALUE"""),"Fantastic Four (1998) #586") -> Fantastic Four (1998) #586 | E50: =IFERROR(__xludf.DUMMYFUNCTION("""COMPUTED_VALUE"""),FALSE) -> FALSE | F50: =IFERROR(__xludf.DUMMYFUNCTION("""COMPUTED_VALUE"""),"Thor #359") -> Thor #359
...

Sheet RUNS
A1: Title | B1: Run ID | C1: Track | D1: Writer | E1: Artists | F1: Series (and Issues) | G1: Issue Count | H1: Start Year | I1: End Year | J1: In Sheet | K1: Status | L1: Tier | M1: Why | N1: Notes | O1: Block | P1: Sequence | Q1: Spine | R1: Rating | S1: Readiness | T1: Hard Prereqs | U1: Hard Read | V1: Hard Left | W1: Soft Prereqs | X1: Soft Read | Y1: Soft Left | Z1: Unlocks | AA1: Completed | AB1: Left | AC1: % Done | AD1: Standalone
A2: Avengers Origin | B2: avengers-origin | C2: Avengers | D2: Stan Lee | F2: Avengers #1, 4, 16 | G2: =COUNTIF(Reading_Order[Run ID], B2) -> 3 | H2: 1963 | I2: 1965 | J2: =$G2>0 -> TRUE | K2: =IF($G2=0,"—",IF($AA2=$G2,"read",IF($AA2>0,"reading","unread"))) -> unread | L2: 4 | M2: Formation and the Kooky Quartet roster | O2: 1 | P2: 1 | Q2: FALSE | S2: =IF($V2>0, "blocked", IF($Y2=0, "ready-all", "ready-hard")) -> ready-all | T2: =COUNTIFS(Prerequisites[Run ID], $B2, Prerequisites[Type], "hard") -> 0 | U2: =COUNTIFS(Prerequisites[Run ID], $B2, Prerequisites[Type], "hard", Prerequisites[Satisfied], TRUE) -> 0 | V2: =T2-U2 -> 0 | W2: =COUNTIFS(Prerequisites[Run ID], $B2, Prerequisites[Type], "soft") -> 0 | X2: =COUNTIFS(Prerequisites[Run ID], $B2, Prerequisites[Type], "soft", Prerequisites[Satisfied], TRUE) -> 0 | Y2: =W2-X2 -> 0 | Z2: =COUNTIFS(Prerequisites[Prereq Run ID],$B2,Prerequisites[Type], "hard") -> 1 | AA2: =COUNTIFS(Reading_Order[Run ID], $B2, Reading_Order[Completed], TRUE) -> 0 | AB2: =$G2-$AA2 -> 3 | AC2: =AA2/(AB2+AA2) -> 0 | AD2: =IF(T2<1, TRUE, FALSE) -> TRUE
A3: The Kree-Skrull War | B3: kree-skrull-war | C3: Avengers | D3: Roy Thomas | E3: Neal Adams | F3: Avengers #89-97 | G3: =COUNTIF(Reading_Order[Run ID], B3) -> 9 | H3: 1971 | I3: 1972 | J3: =$G3>0 -> TRUE | K3: =IF($G3=0,"—",IF($AA3=$G3,"read",IF($AA3>0,"reading","unread"))) -> unread | L3: 2 | M3: The first Marvel event, and still readable | O3: 1 | P3: 2 | Q3: FALSE | S3: =IF($V3>0, "blocked", IF($Y3=0, "ready-all", "ready-hard")) -> blocked | T3: =COUNTIFS(Prerequisites[Run ID], $B3, Prerequisites[Type], "hard") -> 1 | U3: =COUNTIFS(Prerequisites[Run ID], $B3, Prerequisites[Type], "hard", Prerequisites[Satisfied], TRUE) -> 0 | V3: =T3-U3 -> 1 | W3: =COUNTIFS(Prerequisites[Run ID], $B3, Prerequisites[Type], "soft") -> 0 | X3: =COUNTIFS(Prerequisites[Run ID], $B3, Prerequisites[Type], "soft", Prerequisites[Satisfied], TRUE) -> 0 | Y3: =W3-X3 -> 0 | Z3: =COUNTIFS(Prerequisites[Prereq Run ID],$B3,Prerequisites[Type], "hard") -> 1 | AA3: =COUNTIFS(Reading_Order[Run ID], $B3, Reading_Order[Completed], TRUE) -> 0 | AB3: =$G3-$AA3 -> 9 | AC3: =AA3/(AB3+AA3) -> 0 | AD3: =IF(T3<1, TRUE, FALSE) -> FALSE
A4: Stern's Avengers | B4: stern-avengers | C4: Avengers | D4: Roger Stern | E4: John Buscema | F4: Avengers #227-285 | G4: =COUNTIF(Reading_Order[Run ID], B4) -> 131 | H4: 1983 | I4: 1987 | J4: =$G4>0 -> TRUE | K4: =IF($G4=0,"—",IF($AA4=$G4,"read",IF($AA4>0,"reading","unread"))) -> unread | L4: 4 | M4: Under Siege, and the best Monica Rambeau material anywhere | O4: 1 | P4: 3 | Q4: FALSE | S4: =IF($V4>0, "blocked", IF($Y4=0, "ready-all", "ready-hard")) -> blocked | T4: =COUNTIFS(Prerequisites[Run ID], $B4, Prerequisites[Type], "hard") -> 1 | U4: =COUNTIFS(Prerequisites[Run ID], $B4, Prerequisites[Type], "hard", Prerequisites[Satisfied], TRUE) -> 0 | V4: =T4-U4 -> 1 | W4: =COUNTIFS(Prerequisites[Run ID], $B4, Prerequisites[Type], "soft") -> 3 | X4: =COUNTIFS(Prerequisites[Run ID], $B4, Prerequisites[Type], "soft", Prerequisites[Satisfied], TRUE) -> 0 | Y4: =W4-X4 -> 3 | Z4: =COUNTIFS(Prerequisites[Prereq Run ID],$B4,Prerequisites[Type], "hard") -> 0 | AA4: =COUNTIFS(Reading_Order[Run ID], $B4, Reading_Order[Completed], TRUE) -> 0 | AB4: =$G4-$AA4 -> 131 | AC4: =AA4/(AB4+AA4) -> 0 | AD4: =IF(T4<1, TRUE, FALSE) -> FALSE
A5: Busiek's Avengers + Thunderbolts | B5: busiek-avengers | C5: Avengers | D5: Kurt Busiek | E5: George Perez | F5: Thunderbolts (1997) #0-44; Avengers (1998) #0-56; Iron Man (1998) #7; Captain America (1998) #8; Quicksilver (1997) #10; Avengers: Forever (1998) #1-12; Avengers Annual (1999); Avengers Annual (2000); Maximum Security #1-3; Avengers: The Ultron Imperative; Avengers Annual (2001) | G5: =COUNTIF(Reading_Order[Run ID], B5) -> 154 | H5: 1997 | I5: 2002 | J5: =$G5>0 -> TRUE | K5: =IF($G5=0,"—",IF($AA5=$G5,"read",IF($AA5>0,"reading","unread"))) -> unread | L5: 2 | M5: The best 'how the Marvel Universe works' run ever written | O5: 2 | P5: 1 | Q5: TRUE | S5: =IF($V5>0, "blocked", IF($Y5=0, "ready-all", "ready-hard")) -> ready-hard | T5: =COUNTIFS(Prerequisites[Run ID], $B5, Prerequisites[Type], "hard") -> 0 | U5: =COUNTIFS(Prerequisites[Run ID], $B5, Prerequisites[Type], "hard", Prerequisites[Satisfied], TRUE) -> 0 | V5: =T5-U5 -> 0 | W5: =COUNTIFS(Prerequisites[Run ID], $B5, Prerequisites[Type], "soft") -> 4 | X5: =COUNTIFS(Prerequisites[Run ID], $B5, Prerequisites[Type], "soft", Prerequisites[Satisfied], TRUE) -> 0 | Y5: =W5-X5 -> 4 | Z5: =COUNTIFS(Prerequisites[Prereq Run ID],$B5,Prerequisites[Type], "hard") -> 1 | AA5: =COUNTIFS(Reading_Order[Run ID], $B5, Reading_Order[Completed], TRUE) -> 0 | AB5: =$G5-$AA5 -> 154 | AC5: =AA5/(AB5+AA5) -> 0 | AD5: =IF(T5<1, TRUE, FALSE) -> TRUE
A6: Avengers: Disassembled | B6: bendis-disassembled | C6: Avengers | D6: Brian Michael Bendis | F6: Avengers (1999) #500-503; Avengers Finale | G6: =COUNTIF(Reading_Order[Run ID], B6) -> 5 | H6: 2004 | I6: 2005 | J6: =$G6>0 -> TRUE | K6: =IF($G6=0,"—",IF($AA6=$G6,"read",IF($AA6>0,"reading","unread"))) -> unread | L6: 2 | M6: The break that starts the modern era | O6: 2 | P6: 2 | Q6: TRUE | S6: =IF($V6>0, "blocked", IF($Y6=0, "ready-all", "ready-hard")) -> blocked | T6: =COUNTIFS(Prerequisites[Run ID], $B6, Prerequisites[Type], "hard") -> 1 | U6: =COUNTIFS(Prerequisites[Run ID], $B6, Prerequisites[Type], "hard", Prerequisites[Satisfied], TRUE) -> 0 | V6: =T6-U6 -> 1 | W6: =COUNTIFS(Prerequisites[Run ID], $B6, Prerequisites[Type], "soft") -> 2 | X6: =COUNTIFS(Prerequisites[Run ID], $B6, Prerequisites[Type], "soft", Prerequisites[Satisfied], TRUE) -> 0 | Y6: =W6-X6 -> 2 | Z6: =COUNTIFS(Prerequisites[Prereq Run ID],$B6,Prerequisites[Type], "hard") -> 4 | AA6: =COUNTIFS(Reading_Order[Run ID], $B6, Reading_Order[Completed], TRUE) -> 0 | AB6: =$G6-$AA6 -> 5 | AC6: =AA6/(AB6+AA6) -> 0 | AD6: =IF(T6<1, TRUE, FALSE) -> FALSE
A7: New Avengers Breakout | B7: bendis-breakout | C7: Avengers | D7: Brian Michael Bendis | F7: The Pulse #1-9; Secret War #1-5; New Avengers #1-10; Young Avengers #1-8; The Sentry #1-5; The Sentry/Fantastic Four; The Sentry/X-Men; The Sentry/Spider-Man; The Sentry/Hulk; The Sentry vs. The Void | G7: =COUNTIF(Reading_Order[Run ID], B7) -> 48 | H7: 2004 | I7: 2005 | J7: =$G7>0 -> TRUE | K7: =IF($G7=0,"—",IF($AA7=$G7,"read",IF($AA7>0,"reading","unread"))) -> unread | L7: 2 | M7: The New Avengers launch; the status quo for a decade | O7: 2 | P7: 3 | Q7: TRUE | S7: =IF($V7>0, "blocked", IF($Y7=0, "ready-all", "ready-hard")) -> blocked | T7: =COUNTIFS(Prerequisites[Run ID], $B7, Prerequisites[Type], "hard") -> 1 | U7: =COUNTIFS(Prerequisites[Run ID], $B7, Prerequisites[Type], "hard", Prerequisites[Satisfied], TRUE) -> 0 | V7: =T7-U7 -> 1 | W7: =COUNTIFS(Prerequisites[Run ID], $B7, Prerequisites[Type], "soft") -> 1 | X7: =COUNTIFS(Prerequisites[Run ID], $B7, Prerequisites[Type], "soft", Prerequisites[Satisfied], TRUE) -> 0 | Y7: =W7-X7 -> 1 | Z7: =COUNTIFS(Prerequisites[Prereq Run ID],$B7,Prerequisites[Type], "hard") -> 2 | AA7: =COUNTIFS(Reading_Order[Run ID], $B7, Reading_Order[Completed], TRUE) -> 0 | AB7: =$G7-$AA7 -> 48 | AC7: =AA7/(AB7+AA7) -> 0 | AD7: =IF(T7<1, TRUE, FALSE) -> FALSE
A8: House of M | B8: bendis-house-of-m | C8: Avengers | D8: Brian Michael Bendis | F8: Young Avengers Special #1; Excalibur (2004) #8-14; House of M #1-8; Wolverine #33-35; The Pulse #10; Decimation: House of M – The Day After | G8: =COUNTIF(Reading_Order[Run ID], B8) -> 42 | H8: 2005 | I8: 2006 | J8: =$G8>0 -> TRUE | K8: =IF($G8=0,"—",IF($AA8=$G8,"read",IF($AA8>0,"reading","unread"))) -> unread | L8: 2 | M8: Hard prereq for Decimation, AvX and the whole X-Men bridge | O8: 2 | P8: 4 | Q8: TRUE | S8: =IF($V8>0, "blocked", IF($Y8=0, "ready-all", "ready-hard")) -> blocked | T8: =COUNTIFS(Prerequisites[Run ID], $B8, Prerequisites[Type], "hard") -> 2 | U8: =COUNTIFS(Prerequisites[Run ID], $B8, Prerequisites[Type], "hard", Prerequisites[Satisfied], TRUE) -> 0 | V8: =T8-U8 -> 2 | W8: =COUNTIFS(Prerequisites[Run ID], $B8, Prerequisites[Type], "soft") -> 2 | X8: =COUNTIFS(Prerequisites[Run ID], $B8, Prerequisites[Type], "soft", Prerequisites[Satisfied], TRUE) -> 0 | Y8: =W8-X8 -> 2 | Z8: =COUNTIFS(Prerequisites[Prereq Run ID],$B8,Prerequisites[Type], "hard") -> 4 | AA8: =COUNTIFS(Reading_Order[Run ID], $B8, Reading_Order[Completed], TRUE) -> 0 | AB8: =$G8-$AA8 -> 42 | AC8: =AA8/(AB8+AA8) -> 0 | AD8: =IF(T8<1, TRUE, FALSE) -> FALSE
A9: Civil War | B9: bendis-civil-war | C9: Avengers | D9: Brian Michael Bendis | F9: New Avengers #11-25; New Avengers Annual #1; New Avengers: Illuminati (2006 one-shot); Spider-Woman: Origin #1-5; The Pulse #11-14; Young Avengers #9-12; Civil War: Young Avengers & Runaways #1-4; Fantastic Four (1998) #536-543; Amazing Spider-Man (1999) #529-538; Civil War #1-7; Civil War: Casualties of War; Civil War: Front Line #1-11; Sensational Spider-Man Annual #1; Captain America (2004) #25; Civil War: The Confession; Civil War: The Initiative; Fallen Son #1-5 | G9: =COUNTIF(Reading_Order[Run ID], B9) -> 60 | H9: 2005 | I9: 2007 | J9: =$G9>0 -> TRUE | K9: =IF($G9=0,"—",IF($AA9=$G9,"read",IF($AA9>0,"reading","unread"))) -> unread | L9: 3 | M9: The line-wide fracture everything after refers back to | O9: 3 | P9: 1 | Q9: FALSE | S9: =IF($V9>0, "blocked", IF($Y9=0, "ready-all", "ready-hard")) -> blocked | T9: =COUNTIFS(Prerequisites[Run ID], $B9, Prerequisites[Type], "hard") -> 1 | U9: =COUNTIFS(Prerequisites[Run ID], $B9, Prerequisites[Type], "hard", Prerequisites[Satisfied], TRUE) -> 0 | V9: =T9-U9 -> 1 | W9: =COUNTIFS(Prerequisites[Run ID], $B9, Prerequisites[Type], "soft") -> 3 | X9: =COUNTIFS(Prerequisites[Run ID], $B9, Prerequisites[Type], "soft", Prerequisites[Satisfied], TRUE) -> 0 | Y9: =W9-X9 -> 3 | Z9: =COUNTIFS(Prerequisites[Prereq Run ID],$B9,Prerequisites[Type], "hard") -> 1 | AA9: =COUNTIFS(Reading_Order[Run ID], $B9, Reading_Order[Completed], TRUE) -> 0 | AB9: =$G9-$AA9 -> 60 | AC9: =AA9/(AB9+AA9) -> 0 | AD9: =IF(T9<1, TRUE, FALSE) -> FALSE
A10: Heinberg's Young Avengers | B10: heinberg-young-avengers | C10: Young Avengers | D10: Allan Heinberg | G10: =COUNTIF(Reading_Order[Run ID], B10) -> 18 | J10: =$G10>0 -> TRUE | K10: =IF($G10=0,"—",IF($AA10=$G10,"read",IF($AA10>0,"reading","unread"))) -> unread | L10: 3 | O10: 1 | P10: 1 | Q10: TRUE | S10: =IF($V10>0, "blocked", IF($Y10=0, "ready-all", "ready-hard")) -> ready-all | T10: =COUNTIFS(Prerequisites[Run ID], $B10, Prerequisites[Type], "hard") -> 0 | U10: =COUNTIFS(Prerequisites[Run ID], $B10, Prerequisites[Type], "hard", Prerequisites[Satisfied], TRUE) -> 0 | V10: =T10-U10 -> 0 | W10: =COUNTIFS(Prerequisites[Run ID], $B10, Prerequisites[Type], "soft") -> 0 | X10: =COUNTIFS(Prerequisites[Run ID], $B10, Prerequisites[Type], "soft", Prerequisites[Satisfied], TRUE) -> 0 | Y10: =W10-X10 -> 0 | Z10: =COUNTIFS(Prerequisites[Prereq Run ID],$B10,Prerequisites[Type], "hard") -> 1 | AA10: =COUNTIFS(Reading_Order[Run ID], $B10, Reading_Order[Completed], TRUE) -> 0 | AB10: =$G10-$AA10 -> 18 | AC10: =AA10/(AB10+AA10) -> 0 | AD10: =IF(T10<1, TRUE, FALSE) -> TRUE
A11: childrens-crusade | B11: childrens-crusade | C11: Young Avengers | D11: Allan Heinberg | G11: =COUNTIF(Reading_Order[Run ID], B11) -> 11 | J11: =$G11>0 -> TRUE | K11: =IF($G11=0,"—",IF($AA11=$G11,"read",IF($AA11>0,"reading","unread"))) -> unread | O11: 1 | P11: 2 | Q11: FALSE | S11: =IF($V11>0, "blocked", IF($Y11=0, "ready-all", "ready-hard")) -> blocked | T11: =COUNTIFS(Prerequisites[Run ID], $B11, Prerequisites[Type], "hard") -> 3 | U11: =COUNTIFS(Prerequisites[Run ID], $B11, Prerequisites[Type], "hard", Prerequisites[Satisfied], TRUE) -> 0 | V11: =T11-U11 -> 3 | W11: =COUNTIFS(Prerequisites[Run ID], $B11, Prerequisites[Type], "soft") -> 1 | X11: =COUNTIFS(Prerequisites[Run ID], $B11, Prerequisites[Type], "soft", Prerequisites[Satisfied], TRUE) -> 0 | Y11: =W11-X11 -> 1 | Z11: =COUNTIFS(Prerequisites[Prereq Run ID],$B11,Prerequisites[Type], "hard") -> 2 | AA11: =COUNTIFS(Reading_Order[Run ID], $B11, Reading_Order[Completed], TRUE) -> 0 | AB11: =$G11-$AA11 -> 11 | AC11: =AA11/(AB11+AA11) -> 0 | AD11: =IF(T11<1, TRUE, FALSE) -> FALSE
A12: Gillen's Loki | B12: gillen-loki | C12: Young Avengers | D12: Kieron Gillen | G12: =COUNTIF(Reading_Order[Run ID], B12) -> 32 | J12: =$G12>0 -> TRUE | K12: =IF($G12=0,"—",IF($AA12=$G12,"read",IF($AA12>0,"reading","unread"))) -> unread | O12: 1 | P12: 3 | Q12: FALSE | S12: =IF($V12>0, "blocked", IF($Y12=0, "ready-all", "ready-hard")) -> blocked | T12: =COUNTIFS(Prerequisites[Run ID], $B12, Prerequisites[Type], "hard") -> 2 | U12: =COUNTIFS(Prerequisites[Run ID], $B12, Prerequisites[Type], "hard", Prerequisites[Satisfied], TRUE) -> 0 | V12: =T12-U12 -> 2 | W12: =COUNTIFS(Prerequisites[Run ID], $B12, Prerequisites[Type], "soft") -> 1 | X12: =COUNTIFS(Prerequisites[Run ID], $B12, Prerequisites[Type], "soft", Prerequisites[Satisfied], TRUE) -> 0 | Y12: =W12-X12 -> 1 | Z12: =COUNTIFS(Prerequisites[Prereq Run ID],$B12,Prerequisites[Type], "hard") -> 1 | AA12: =COUNTIFS(Reading_Order[Run ID], $B12, Reading_Order[Completed], TRUE) -> 0 | AB12: =$G12-$AA12 -> 32 | AC12: =AA12/(AB12+AA12) -> 0 | AD12: =IF(T12<1, TRUE, FALSE) -> FALSE
A13: Gillen's Young Avengers | B13: gillen-young-avengers | C13: Young Avengers | D13: Kieron Gillen | F13: Young Avengers (2005) #1-12; Young Avengers (2013) #1-15; Uncanny X-Men (1981) #526; Avengers: The Children's Crusade #1-9; Avengers: The Children's Crusade - Young Avengers #1; Journey into Mystery (2011) #622-645; Exiled #1; New Mutants (2009) #42-43; The Mighty Thor (2011) #18-21; Marvel NOW! Point One #1 | G13: =COUNTIF(Reading_Order[Run ID], B13) -> 22 | H13: 2005 | I13: 2014 | J13: =$G13>0 -> TRUE | K13: =IF($G13=0,"—",IF($AA13=$G13,"read",IF($AA13>0,"reading","unread"))) -> unread | L13: 3 | M13: The most stylish superhero book of its decade | O13: 1 | P13: 4 | Q13: FALSE | S13: =IF($V13>0, "blocked", IF($Y13=0, "ready-all", "ready-hard")) -> blocked | T13: =COUNTIFS(Prerequisites[Run ID], $B13, Prerequisites[Type], "hard") -> 4 | U13: =COUNTIFS(Prerequisites[Run ID], $B13, Prerequisites[Type], "hard", Prerequisites[Satisfied], TRUE) -> 0 | V13: =T13-U13 -> 4 | W13: =COUNTIFS(Prerequisites[Run ID], $B13, Prerequisites[Type], "soft") -> 1 | X13: =COUNTIFS(Prerequisites[Run ID], $B13, Prerequisites[Type], "soft", Prerequisites[Satisfied], TRUE) -> 0 | Y13: =W13-X13 -> 1 | Z13: =COUNTIFS(Prerequisites[Prereq Run ID],$B13,Prerequisites[Type], "hard") -> 1 | AA13: =COUNTIFS(Reading_Order[Run ID], $B13, Reading_Order[Completed], TRUE) -> 0 | AB13: =$G13-$AA13 -> 22 | AC13: =AA13/(AB13+AA13) -> 0 | AD13: =IF(T13<1, TRUE, FALSE) -> FALSE
A14: The Initiative | B14: bendis-initiative | C14: Avengers | D14: Brian Michael Bendis | F14: New Avengers #26-37; New Avengers Annual #2; The Mighty Avengers #1-11; Avengers: The Initiative #1-13; Avengers: The Initiative Annual #1; World War Hulk #1-5; Thunderbolts #110-121; New Avengers: Illuminati #1-5 | G14: =COUNTIF(Reading_Order[Run ID], B14) -> 70 | H14: 2007 | I14: 2008 | J14: =$G14>0 -> TRUE | K14: =IF($G14=0,"—",IF($AA14=$G14,"read",IF($AA14>0,"reading","unread"))) -> unread | L14: 3 | M14: Hard prereq via World War Hulk | O14: 3 | P14: 2 | Q14: FALSE | S14: =IF($V14>0, "blocked", IF($Y14=0, "ready-all", "ready-hard")) -> blocked | T14: =COUNTIFS(Prerequisites[Run ID], $B14, Prerequisites[Type], "hard") -> 1 | U14: =COUNTIFS(Prerequisites[Run ID], $B14, Prerequisites[Type], "hard", Prerequisites[Satisfied], TRUE) -> 0 | V14: =T14-U14 -> 1 | W14: =COUNTIFS(Prerequisites[Run ID], $B14, Prerequisites[Type], "soft") -> 1 | X14: =COUNTIFS(Prerequisites[Run ID], $B14, Prerequisites[Type], "soft", Prerequisites[Satisfied], TRUE) -> 0 | Y14: =W14-X14 -> 1 | Z14: =COUNTIFS(Prerequisites[Prereq Run ID],$B14,Prerequisites[Type], "hard") -> 1 | AA14: =COUNTIFS(Reading_Order[Run ID], $B14, Reading_Order[Completed], TRUE) -> 0 | AB14: =$G14-$AA14 -> 70 | AC14: =AA14/(AB14+AA14) -> 0 | AD14: =IF(T14<1, TRUE, FALSE) -> FALSE
A15: Secret Invasion | B15: bendis-secret-invasion | C15: Avengers | D15: Brian Michael Bendis | F15: New Avengers #38-47; The Mighty Avengers #12-19; Avengers: The Initiative #14-19; Secret Invasion Prologue; Secret Invasion #1-8; Secret Invasion: Requiem #1; Secret Invasion: Dark Reign #1; Thunderbolts #122-125 | G15: =COUNTIF(Reading_Order[Run ID], B15) -> 46 | H15: 2008 | I15: 2009 | J15: =$G15>0 -> TRUE | K15: =IF($G15=0,"—",IF($AA15=$G15,"read",IF($AA15>0,"reading","unread"))) -> unread | L15: 3 | M15: Direct prequel to Secret Warriors, which you've read | O15: 3 | P15: 3 | Q15: FALSE | S15: =IF($V15>0, "blocked", IF($Y15=0, "ready-all", "ready-hard")) -> blocked | T15: =COUNTIFS(Prerequisites[Run ID], $B15, Prerequisites[Type], "hard") -> 1 | U15: =COUNTIFS(Prerequisites[Run ID], $B15, Prerequisites[Type], "hard", Prerequisites[Satisfied], TRUE) -> 0 | V15: =T15-U15 -> 1 | W15: =COUNTIFS(Prerequisites[Run ID], $B15, Prerequisites[Type], "soft") -> 2 | X15: =COUNTIFS(Prerequisites[Run ID], $B15, Prerequisites[Type], "soft", Prerequisites[Satisfied], TRUE) -> 0 | Y15: =W15-X15 -> 2 | Z15: =COUNTIFS(Prerequisites[Prereq Run ID],$B15,Prerequisites[Type], "hard") -> 1 | AA15: =COUNTIFS(Reading_Order[Run ID], $B15, Reading_Order[Completed], TRUE) -> 0 | AB15: =$G15-$AA15 -> 46 | AC15: =AA15/(AB15+AA15) -> 0 | AD15: =IF(T15<1, TRUE, FALSE) -> FALSE
A16: Dark Reign | B16: bendis-dark-reign | C16: Avengers | D16: Brian Michael Bendis | F16: New Avengers #48-60; New Avengers Annual #3; The Mighty Avengers #20-31; Dark Avengers #1-12; Avengers: The Initiative #20-30; Avengers: The Initiative Special #1; New Avengers: The Reunion #1-4; Dark Reign: The Hood #1-5; Dark Reign: The Cabal; Free Comic Book Day 2009: Avengers; Dark Avengers/Uncanny X-Men: Utopia #1; Uncanny X-Men #513-514; Dark Avengers/Uncanny X-Men: Exodus #1 | G16: =COUNTIF(Reading_Order[Run ID], B16) -> 65 | H16: 2009 | I16: 2010 | J16: =$G16>0 -> TRUE | K16: =IF($G16=0,"—",IF($AA16=$G16,"read",IF($AA16>0,"reading","unread"))) -> unread | L16: 3 | M16: Osborn in charge; the setup for Siege | O16: 3 | P16: 4 | Q16: FALSE | S16: =IF($V16>0, "blocked", IF($Y16=0, "ready-all", "ready-hard")) -> blocked | T16: =COUNTIFS(Prerequisites[Run ID], $B16, Prerequisites[Type], "hard") -> 1 | U16: =COUNTIFS(Prerequisites[Run ID], $B16, Prerequisites[Type], "hard", Prerequisites[Satisfied], TRUE) -> 0 | V16: =T16-U16 -> 1 | W16: =COUNTIFS(Prerequisites[Run ID], $B16, Prerequisites[Type], "soft") -> 0 | X16: =COUNTIFS(Prerequisites[Run ID], $B16, Prerequisites[Type], "soft", Prerequisites[Satisfied], TRUE) -> 0 | Y16: =W16-X16 -> 0 | Z16: =COUNTIFS(Prerequisites[Prereq Run ID],$B16,Prerequisites[Type], "hard") -> 1 | AA16: =COUNTIFS(Reading_Order[Run ID], $B16, Reading_Order[Completed], TRUE) -> 0 | AB16: =$G16-$AA16 -> 65 | AC16: =AA16/(AB16+AA16) -> 0 | AD16: =IF(T16<1, TRUE, FALSE) -> FALSE
A17: Siege | B17: bendis-siege | C17: Avengers | D17: Brian Michael Bendis | F17: Dark Reign: The List – Avengers; Dark Avengers #13-16; Dark Avengers Annual #1; The Mighty Avengers #32-36; New Avengers #61-64; New Avengers Finale #1; Avengers: The Initiative #31-35; Siege: The Cabal #1; Origins of Siege #1; Siege Prologue; Siege #1-4; Siege: Embedded #1-4 | G17: =COUNTIF(Reading_Order[Run ID], B17) -> 35 | H17: 2009 | I17: 2010 | J17: =$G17>0 -> TRUE | K17: =IF($G17=0,"—",IF($AA17=$G17,"read",IF($AA17>0,"reading","unread"))) -> unread | L17: 3 | M17: Asgard falls; leads directly into Hickman | O17: 3 | P17: 5 | Q17: FALSE | S17: =IF($V17>0, "blocked", IF($Y17=0, "ready-all", "ready-hard")) -> blocked | T17: =COUNTIFS(Prerequisites[Run ID], $B17, Prerequisites[Type], "hard") -> 1 | U17: =COUNTIFS(Prerequisites[Run ID], $B17, Prerequisites[Type], "hard", Prerequisites[Satisfied], TRUE) -> 0 | V17: =T17-U17 -> 1 | W17: =COUNTIFS(Prerequisites[Run ID], $B17, Prerequisites[Type], "soft") -> 1 | X17: =COUNTIFS(Prerequisites[Run ID], $B17, Prerequisites[Type], "soft", Prerequisites[Satisfied], TRUE) -> 0 | Y17: =W17-X17 -> 1 | Z17: =COUNTIFS(Prerequisites[Prereq Run ID],$B17,Prerequisites[Type], "hard") -> 1 | AA17: =COUNTIFS(Reading_Order[Run ID], $B17, Reading_Order[Completed], TRUE) -> 0 | AB17: =$G17-$AA17 -> 35 | AC17: =AA17/(AB17+AA17) -> 0 | AD17: =IF(T17<1, TRUE, FALSE) -> FALSE
A18: Heroric Age | B18: bendis-heroic-age | C18: Avengers | D18: Brian Michael Bendis | F18: Enter the Heroic Age #1; Avengers: Prime #1-5; Avengers (2010) #1-12, #12.1; New Avengers (2010) #1-13; Secret Avengers #1-12, #12.1; Avengers Academy #1-14.1; Amazing Spider-Man (1999) #661-662; Avengers: The Children's Crusade #1-9; Children's Crusade: Young Avengers #1 | G18: =COUNTIF(Reading_Order[Run ID], B18) -> 71 | H18: 2010 | I18: 2012 | J18: =$G18>0 -> TRUE | K18: =IF($G18=0,"—",IF($AA18=$G18,"read",IF($AA18>0,"reading","unread"))) -> unread | L18: 4 | M18: The reset, and where Children's Crusade lives | O18: 4 | P18: 1 | Q18: FALSE | S18: =IF($V18>0, "blocked", IF($Y18=0, "ready-all", "ready-hard")) -> blocked | T18: =COUNTIFS(Prerequisites[Run ID], $B18, Prerequisites[Type], "hard") -> 1 | U18: =COUNTIFS(Prerequisites[Run ID], $B18, Prerequisites[Type], "hard", Prerequisites[Satisfied], TRUE) -> 0 | V18: =T18-U18 -> 1 | W18: =COUNTIFS(Prerequisites[Run ID], $B18, Prerequisites[Type], "soft") -> 2 | X18: =COUNTIFS(Prerequisites[Run ID], $B18, Prerequisites[Type], "soft", Prerequisites[Satisfied], TRUE) -> 0 | Y18: =W18-X18 -> 2 | Z18: =COUNTIFS(Prerequisites[Prereq Run ID],$B18,Prerequisites[Type], "hard") -> 1 | AA18: =COUNTIFS(Reading_Order[Run ID], $B18, Reading_Order[Completed], TRUE) -> 0 | AB18: =$G18-$AA18 -> 71 | AC18: =AA18/(AB18+AA18) -> 0 | AD18: =IF(T18<1, TRUE, FALSE) -> FALSE
A19: Fear Itself | B19: bendis-fear-itself | C19: Avengers | D19: Brian Michael Bendis | F19: Fear Itself: The Book of the Skull #1; Fear Itself #1-7, #7.1-7.3; Fear Itself: The Home Front #1-7; Avengers (2010) #13-24; Avengers (2010) Annual #1; New Avengers (2010) #14-23, #16.1; New Avengers (1996) Annual #1; Secret Avengers #13-25; Avengers Academy #15-20; Avengers Assemble #1-8 | G19: =COUNTIF(Reading_Order[Run ID], B19) -> 88 | H19: 2011 | I19: 2012 | J19: =$G19>0 -> TRUE | K19: =IF($G19=0,"—",IF($AA19=$G19,"read",IF($AA19>0,"reading","unread"))) -> unread | L19: 4 | M19: A Thor event more than an Avengers one | O19: 4 | P19: 2 | Q19: FALSE | S19: =IF($V19>0, "blocked", IF($Y19=0, "ready-all", "ready-hard")) -> blocked | T19: =COUNTIFS(Prerequisites[Run ID], $B19, Prerequisites[Type], "hard") -> 1 | U19: =COUNTIFS(Prerequisites[Run ID], $B19, Prerequisites[Type], "hard", Prerequisites[Satisfied], TRUE) -> 0 | V19: =T19-U19 -> 1 | W19: =COUNTIFS(Prerequisites[Run ID], $B19, Prerequisites[Type], "soft") -> 2 | X19: =COUNTIFS(Prerequisites[Run ID], $B19, Prerequisites[Type], "soft", Prerequisites[Satisfied], TRUE) -> 0 | Y19: =W19-X19 -> 2 | Z19: =COUNTIFS(Prerequisites[Prereq Run ID],$B19,Prerequisites[Type], "hard") -> 1 | AA19: =COUNTIFS(Reading_Order[Run ID], $B19, Reading_Order[Completed], TRUE) -> 0 | AB19: =$G19-$AA19 -> 88 | AC19: =AA19/(AB19+AA19) -> 0 | AD19: =IF(T19<1, TRUE, FALSE) -> FALSE
A20: Avengers vs. X-Men | B20: bendis-avx | C20: Avengers | D20: Brian Michael Bendis | F20: Avengers: X-Sanction #1-4; Avengers (2010) #24.1, #25-30; Avengers vs. X-Men #0, #1-12; New Avengers (2010) #24-30; Secret Avengers #26-28; Uncanny X-Men (2012) #11-20; Wolverine and the X-Men #9-15, #18; AvX: Consequences #1-5 | G20: =COUNTIF(Reading_Order[Run ID], B20) -> 68 | H20: 2011 | I20: 2012 | J20: =$G20>0 -> TRUE | K20: =IF($G20=0,"—",IF($AA20=$G20,"read",IF($AA20>0,"reading","unread"))) -> unread | L20: 4 | M20: Hope Summers is the plot — needs the Messiah Trilogy to land | O20: 4 | P20: 3 | Q20: FALSE | S20: =IF($V20>0, "blocked", IF($Y20=0, "ready-all", "ready-hard")) -> blocked | T20: =COUNTIFS(Prerequisites[Run ID], $B20, Prerequisites[Type], "hard") -> 4 | U20: =COUNTIFS(Prerequisites[Run ID], $B20, Prerequisites[Type], "hard", Prerequisites[Satisfied], TRUE) -> 0 | V20: =T20-U20 -> 4 | W20: =COUNTIFS(Prerequisites[Run ID], $B20, Prerequisites[Type], "soft") -> 1 | X20: =COUNTIFS(Prerequisites[Run ID], $B20, Prerequisites[Type], "soft", Prerequisites[Satisfied], TRUE) -> 0 | Y20: =W20-X20 -> 1 | Z20: =COUNTIFS(Prerequisites[Prereq Run ID],$B20,Prerequisites[Type], "hard") -> 2 | AA20: =COUNTIFS(Reading_Order[Run ID], $B20, Reading_Order[Completed], TRUE) -> 0 | AB20: =$G20-$AA20 -> 68 | AC20: =AA20/(AB20+AA20) -> 0 | AD20: =IF(T20<1, TRUE, FALSE) -> FALSE
A21: Age of Ultron | B21: bendis-ultron | C21: Avengers | D21: Brian Michael Bendis | F21: Avengers (2010) #31-34; New Avengers (2010) #31-34; Secret Avengers #29-37; Marvel NOW! Point One #1; Age of Ultron #1-10, #10AI | G21: =COUNTIF(Reading_Order[Run ID], B21) -> 35 | H21: 2012 | I21: 2013 | J21: =$G21>0 -> TRUE | K21: =IF($G21=0,"—",IF($AA21=$G21,"read",IF($AA21>0,"reading","unread"))) -> unread | L21: 4 | M21: Its ending leads into Hickman's Secret Wars | O21: 4 | P21: 4 | Q21: FALSE | S21: =IF($V21>0, "blocked", IF($Y21=0, "ready-all", "ready-hard")) -> blocked | T21: =COUNTIFS(Prerequisites[Run ID], $B21, Prerequisites[Type], "hard") -> 1 | U21: =COUNTIFS(Prerequisites[Run ID], $B21, Prerequisites[Type], "hard", Prerequisites[Satisfied], TRUE) -> 0 | V21: =T21-U21 -> 1 | W21: =COUNTIFS(Prerequisites[Run ID], $B21, Prerequisites[Type], "soft") -> 0 | X21: =COUNTIFS(Prerequisites[Run ID], $B21, Prerequisites[Type], "soft", Prerequisites[Satisfied], TRUE) -> 0 | Y21: =W21-X21 -> 0 | Z21: =COUNTIFS(Prerequisites[Prereq Run ID],$B21,Prerequisites[Type], "hard") -> 1 | AA21: =COUNTIFS(Reading_Order[Run ID], $B21, Reading_Order[Completed], TRUE) -> 0 | AB21: =$G21-$AA21 -> 35 | AC21: =AA21/(AB21+AA21) -> 0 | AD21: =IF(T21<1, TRUE, FALSE) -> FALSE
A22: Ewing Mighty Avengers | B22: ewing-mighty-avengers | C22: Avengers | D22: Al Ewing | F22: Avengers Assemble (2012) #14-15; The Mighty Avengers (2013) #1-14; Avengers: Ultron Forever; New Avengers: Ultron Forever; Uncanny Avengers: Ultron Forever; Captain America and the Mighty Avengers #1-9; Captain Britain and the Mighty Defenders #1-2 | G22: =COUNTIF(Reading_Order[Run ID], B22) -> 31 | H22: 2012 | I22: 2015 | J22: =$G22>0 -> TRUE | K22: =IF($G22=0,"—",IF($AA22=$G22,"read",IF($AA22>0,"reading","unread"))) -> unread | L22: 3 | M22: Blue Marvel, Monica Rambeau, the street-level Avengers nobody else writes | O22: 5 | P22: 1 | Q22: TRUE | S22: =IF($V22>0, "blocked", IF($Y22=0, "ready-all", "ready-hard")) -> blocked | T22: =COUNTIFS(Prerequisites[Run ID], $B22, Prerequisites[Type], "hard") -> 1 | U22: =COUNTIFS(Prerequisites[Run ID], $B22, Prerequisites[Type], "hard", Prerequisites[Satisfied], TRUE) -> 0 | V22: =T22-U22 -> 1 | W22: =COUNTIFS(Prerequisites[Run ID], $B22, Prerequisites[Type], "soft") -> 5 | X22: =COUNTIFS(Prerequisites[Run ID], $B22, Prerequisites[Type], "soft", Prerequisites[Satisfied], TRUE) -> 0 | Y22: =W22-X22 -> 5 | Z22: =COUNTIFS(Prerequisites[Prereq Run ID],$B22,Prerequisites[Type], "hard") -> 1 | AA22: =COUNTIFS(Reading_Order[Run ID], $B22, Reading_Order[Completed], TRUE) -> 0 | AB22: =$G22-$AA22 -> 31 | AC22: =AA22/(AB22+AA22) -> 0 | AD22: =IF(T22<1, TRUE, FALSE) -> FALSE
A23: Ewing Ultimates | B23: ewing-ultimates | C23: Avengers | D23: Al Ewing | F23: Contest of Champions #1-10; All New, All-Different Avengers #0; The Ultimates (2015) #1-12; The Ultimates (2017) 2 #1-9, 100 | G23: =COUNTIF(Reading_Order[Run ID], B23) -> 33 | H23: 2015 | I23: 2017 | J23: =$G23>0 -> TRUE | K23: =IF($G23=0,"—",IF($AA23=$G23,"read",IF($AA23>0,"reading","unread"))) -> unread | L23: 2 | M23: TARGET — direct sequel to Hickman's Secret Wars, and READY the moment you finish it | O23: 5 | P23: 2 | Q23: TRUE | S23: =IF($V23>0, "blocked", IF($Y23=0, "ready-all", "ready-hard")) -> blocked | T23: =COUNTIFS(Prerequisites[Run ID], $B23, Prerequisites[Type], "hard") -> 2 | U23: =COUNTIFS(Prerequisites[Run ID], $B23, Prerequisites[Type], "hard", Prerequisites[Satisfied], TRUE) -> 0 | V23: =T23-U23 -> 2 | W23: =COUNTIFS(Prerequisites[Run ID], $B23, Prerequisites[Type], "soft") -> 1 | X23: =COUNTIFS(Prerequisites[Run ID], $B23, Prerequisites[Type], "soft", Prerequisites[Satisfied], TRUE) -> 0 | Y23: =W23-X23 -> 1 | Z23: =COUNTIFS(Prerequisites[Prereq Run ID],$B23,Prerequisites[Type], "hard") -> 1 | AA23: =COUNTIFS(Reading_Order[Run ID], $B23, Reading_Order[Completed], TRUE) -> 0 | AB23: =$G23-$AA23 -> 33 | AC23: =AA23/(AB23+AA23) -> 0 | AD23: =IF(T23<1, TRUE, FALSE) -> FALSE
A24: Ewing New Avengers | B24: ewing-new-avengers | C24: Avengers | D24: Al Ewing | F24: New Avengers (2015) #1-18; U.S. Avengers #1-12 | G24: =COUNTIF(Reading_Order[Run ID], B24) -> 33 | H24: 2015 | I24: 2017 | J24: =$G24>0 -> TRUE | K24: =IF($G24=0,"—",IF($AA24=$G24,"read",IF($AA24>0,"reading","unread"))) -> unread | L24: 3 | M24: U.S.Avengers; Ewing at his most playful | O24: 5 | P24: 3 | Q24: TRUE | S24: =IF($V24>0, "blocked", IF($Y24=0, "ready-all", "ready-hard")) -> blocked | T24: =COUNTIFS(Prerequisites[Run ID], $B24, Prerequisites[Type], "hard") -> 2 | U24: =COUNTIFS(Prerequisites[Run ID], $B24, Prerequisites[Type], "hard", Prerequisites[Satisfied], TRUE) -> 0 | V24: =T24-U24 -> 2 | W24: =COUNTIFS(Prerequisites[Run ID], $B24, Prerequisites[Type], "soft") -> 1 | X24: =COUNTIFS(Prerequisites[Run ID], $B24, Prerequisites[Type], "soft", Prerequisites[Satisfied], TRUE) -> 0 | Y24: =W24-X24 -> 1 | Z24: =COUNTIFS(Prerequisites[Prereq Run ID],$B24,Prerequisites[Type], "hard") -> 1 | AA24: =COUNTIFS(Reading_Order[Run ID], $B24, Reading_Order[Completed], TRUE) -> 0 | AB24: =$G24-$AA24 -> 33 | AC24: =AA24/(AB24+AA24) -> 0 | AD24: =IF(T24<1, TRUE, FALSE) -> FALSE
... A33: Black Panther Origin | B33: black-panther-origin | C33: Black Panther | D33: Stan Lee | F33: Fantastic Four #52-53 | G33: =COUNTIF(Reading_Order[Run ID], B33) -> 10 | H33: 1966 | I33: 1966 | J33: =$G33>0 -> TRUE | K33: =IF($G33=0,"—",IF($AA33=$G33,"read",IF($AA33>0,"reading","unread"))) -> unread | L33: 4 | M33: Two issues of peak Kirby | O33: 1 | P33: 1 | Q33: TRUE | S33: =IF($V33>0, "blocked", IF($Y33=0, "ready-all", "ready-hard")) -> ready-hard | T33: =COUNTIFS(Prerequisites[Run ID], $B33, Prerequisites[Type], "hard") -> 0 | U33: =COUNTIFS(Prerequisites[Run ID], $B33, Prerequisites[Type], "hard", Prerequisites[Satisfied], TRUE) -> 0 | V33: =T33-U33 -> 0 | W33: =COUNTIFS(Prerequisites[Run ID], $B33, Prerequisites[Type], "soft") -> 1 | X33: =COUNTIFS(Prerequisites[Run ID], $B33, Prerequisites[Type], "soft", Prerequisites[Satisfied], TRUE) -> 0 | Y33: =W33-X33 -> 1 | Z33: =COUNTIFS(Prerequisites[Prereq Run ID],$B33,Prerequisites[Type], "hard") -> 1 | AA33: =COUNTIFS(Reading_Order[Run ID], $B33, Reading_Order[Completed], TRUE) -> 0 | AB33: =$G33-$AA33 -> 10 | AC33: =AA33/(AB33+AA33) -> 0 | AD33: =IF(T33<1, TRUE, FALSE) -> TRUE
A34: Panther's Rage | B34: mcgregor-panthers-rage | C34: Black Panther | D34: Don McGregor | E34: Rich Buckler, Billy Graham | F34: Jungle Action (1972) #6-22, #24 | G34: =COUNTIF(Reading_Order[Run ID], B34) -> 19 | H34: 1973 | I34: 1976 | J34: =$G34>0 -> TRUE | K34: =IF($G34=0,"—",IF($AA34=$G34,"read",IF($AA34>0,"reading","unread"))) -> unread | L34: 3 | M34: Arguably Marvel's first graphic novel, serialised 13 issues at a time | O34: 1 | P34: 2 | Q34: TRUE | S34: =IF($V34>0, "blocked", IF($Y34=0, "ready-all", "ready-hard")) -> ready-hard | T34: =COUNTIFS(Prerequisites[Run ID], $B34, Prerequisites[Type], "hard") -> 0 | U34: =COUNTIFS(Prerequisites[Run ID], $B34, Prerequisites[Type], "hard", Prerequisites[Satisfied], TRUE) -> 0 | V34: =T34-U34 -> 0 | W34: =COUNTIFS(Prerequisites[Run ID], $B34, Prerequisites[Type], "soft") -> 1 | X34: =COUNTIFS(Prerequisites[Run ID], $B34, Prerequisites[Type], "soft", Prerequisites[Satisfied], TRUE) -> 0 | Y34: =W34-X34 -> 1 | Z34: =COUNTIFS(Prerequisites[Prereq Run ID],$B34,Prerequisites[Type], "hard") -> 2 | AA34: =COUNTIFS(Reading_Order[Run ID], $B34, Reading_Order[Completed], TRUE) -> 0 | AB34: =$G34-$AA34 -> 19 | AC34: =AA34/(AB34+AA34) -> 0 | AD34: =IF(T34<1, TRUE, FALSE) -> TRUE
A35: Panther's Quest | B35: mcgregor-panthers-quest | C35: Black Panther | D35: Don McGregor | F35: Marvel Comics Presents #13-37 | G35: =COUNTIF(Reading_Order[Run ID], B35) -> 25 | J35: =$G35>0 -> TRUE | K35: =IF($G35=0,"—",IF($AA35=$G35,"read",IF($AA35>0,"reading","unread"))) -> unread | O35: 1 | P35: 3 | Q35: FALSE | S35: =IF($V35>0, "blocked", IF($Y35=0, "ready-all", "ready-hard")) -> blocked | T35: =COUNTIFS(Prerequisites[Run ID], $B35, Prerequisites[Type], "hard") -> 2 | U35: =COUNTIFS(Prerequisites[Run ID], $B35, Prerequisites[Type], "hard", Prerequisites[Satisfied], TRUE) -> 0 | V35: =T35-U35 -> 2 | W35: =COUNTIFS(Prerequisites[Run ID], $B35, Prerequisites[Type], "soft") -> 0 | X35: =COUNTIFS(Prerequisites[Run ID], $B35, Prerequisites[Type], "soft", Prerequisites[Satisfied], TRUE) -> 0 | Y35: =W35-X35 -> 0 | Z35: =COUNTIFS(Prerequisites[Prereq Run ID],$B35,Prerequisites[Type], "hard") -> 0 | AA35: =COUNTIFS(Reading_Order[Run ID], $B35, Reading_Order[Completed], TRUE) -> 0 | AB35: =$G35-$AA35 -> 25 | AC35: =AA35/(AB35+AA35) -> 0 | AD35: =IF(T35<1, TRUE, FALSE) -> FALSE
A36: Kirby's Black Panther | B36: kirby-black-panther | C36: Black Panther | D36: Jack Kirby | F36: Black Panther (1977) #1-15; Marvel Premiere (1972) #51-53 | G36: =COUNTIF(Reading_Order[Run ID], B36) -> 18 | H36: 1977 | I36: 1979 | J36: =$G36>0 -> TRUE | K36: =IF($G36=0,"—",IF($AA36=$G36,"read",IF($AA36>0,"reading","unread"))) -> unread | L36: 4 | M36: Kirby doing pulp adventure, unrelated to McGregor | O36: 1 | P36: 4 | Q36: FALSE | S36: =IF($V36>0, "blocked", IF($Y36=0, "ready-all", "ready-hard")) -> blocked | T36: =COUNTIFS(Prerequisites[Run ID], $B36, Prerequisites[Type], "hard") -> 1 | U36: =COUNTIFS(Prerequisites[Run ID], $B36, Prerequisites[Type], "hard", Prerequisites[Satisfied], TRUE) -> 0 | V36: =T36-U36 -> 1 | W36: =COUNTIFS(Prerequisites[Run ID], $B36, Prerequisites[Type], "soft") -> 0 | X36: =COUNTIFS(Prerequisites[Run ID], $B36, Prerequisites[Type], "soft", Prerequisites[Satisfied], TRUE) -> 0 | Y36: =W36-X36 -> 0 | Z36: =COUNTIFS(Prerequisites[Prereq Run ID],$B36,Prerequisites[Type], "hard") -> 1 | AA36: =COUNTIFS(Reading_Order[Run ID], $B36, Reading_Order[Completed], TRUE) -> 0 | AB36: =$G36-$AA36 -> 18 | AC36: =AA36/(AB36+AA36) -> 0 | AD36: =IF(T36<1, TRUE, FALSE) -> FALSE
A37: Priest's Black Panther | B37: priest-black-panther | C37: Black Panther | D37: Christopher Priest | E37: Mark Texeira | F37: Black Panther (1998) #1-62; Avengers (1998) #19-23, #57-61, #65-70, #76; Deadpool (1997) #44; Incredible Hulk (2000) #33; Crew #1-7 | G37: =COUNTIF(Reading_Order[Run ID], B37) -> 93 | H37: 1998 | I37: 2003 | J37: =$G37>0 -> TRUE | K37: =IF($G37=0,"—",IF($AA37=$G37,"read",IF($AA37>0,"reading","unread"))) -> unread | L37: 3 | M37: #5 is the best sampling point in the run | O37: 1 | P37: 5 | Q37: TRUE | S37: =IF($V37>0, "blocked", IF($Y37=0, "ready-all", "ready-hard")) -> blocked | T37: =COUNTIFS(Prerequisites[Run ID], $B37, Prerequisites[Type], "hard") -> 1 | U37: =COUNTIFS(Prerequisites[Run ID], $B37, Prerequisites[Type], "hard", Prerequisites[Satisfied], TRUE) -> 0 | V37: =T37-U37 -> 1 | W37: =COUNTIFS(Prerequisites[Run ID], $B37, Prerequisites[Type], "soft") -> 2 | X37: =COUNTIFS(Prerequisites[Run ID], $B37, Prerequisites[Type], "soft", Prerequisites[Satisfied], TRUE) -> 0 | Y37: =W37-X37 -> 2 | Z37: =COUNTIFS(Prerequisites[Prereq Run ID],$B37,Prerequisites[Type], "hard") -> 1 | AA37: =COUNTIFS(Reading_Order[Run ID], $B37, Reading_Order[Completed], TRUE) -> 0 | AB37: =$G37-$AA37 -> 93 | AC37: =AA37/(AB37+AA37) -> 0 | AD37: =IF(T37<1, TRUE, FALSE) -> FALSE
A38: Hudlin's Black Panther | B38: hudlin-black-panther | C38: Black Panther | D38: Reginald Hudlin | F38: Black Panther (2005) #1-41; X-Men (1991) #175-176; Storm #1-6; Fantastic Four (1961) #544-550; Black Panther (2005) Annual #1; Black Panther (2009) #1-12; Doomwar #1-6; Klaws of the Panther #1-4 | G38: =COUNTIF(Reading_Order[Run ID], B38) -> 87 | H38: 2005 | I38: 2010 | J38: =$G38>0 -> TRUE | K38: =IF($G38=0,"—",IF($AA38=$G38,"read",IF($AA38>0,"reading","unread"))) -> unread | L38: 4 | M38: The Storm marriage and Doomwar | O38: 1 | P38: 6 | Q38: FALSE | S38: =IF($V38>0, "blocked", IF($Y38=0, "ready-all", "ready-hard")) -> blocked | T38: =COUNTIFS(Prerequisites[Run ID], $B38, Prerequisites[Type], "hard") -> 1 | U38: =COUNTIFS(Prerequisites[Run ID], $B38, Prerequisites[Type], "hard", Prerequisites[Satisfied], TRUE) -> 0 | V38: =T38-U38 -> 1 | W38: =COUNTIFS(Prerequisites[Run ID], $B38, Prerequisites[Type], "soft") -> 1 | X38: =COUNTIFS(Prerequisites[Run ID], $B38, Prerequisites[Type], "soft", Prerequisites[Satisfied], TRUE) -> 0 | Y38: =W38-X38 -> 1 | Z38: =COUNTIFS(Prerequisites[Prereq Run ID],$B38,Prerequisites[Type], "hard") -> 2 | AA38: =COUNTIFS(Reading_Order[Run ID], $B38, Reading_Order[Completed], TRUE) -> 0 | AB38: =$G38-$AA38 -> 87 | AC38: =AA38/(AB38+AA38) -> 0 | AD38: =IF(T38<1, TRUE, FALSE) -> FALSE
A39: Coates' Black Panther | B39: coates-black-panther | C39: Black Panther | D39: Ta-Nehisi Coates | E39: Brian Stelfreeze | F39: Black Panther (2016) #1-18; Black Panther (2018) #1-25 | G39: =COUNTIF(Reading_Order[Run ID], B39) -> 76 | H39: 2016 | I39: 2021 | J39: =$G39>0 -> TRUE | K39: =IF($G39=0,"—",IF($AA39=$G39,"read",IF($AA39>0,"reading","unread"))) -> unread | L39: 3 | M39: Starts, really, in Hickman's New Avengers — which you'll have read | O39: 1 | P39: 7 | Q39: TRUE | S39: =IF($V39>0, "blocked", IF($Y39=0, "ready-all", "ready-hard")) -> blocked | T39: =COUNTIFS(Prerequisites[Run ID], $B39, Prerequisites[Type], "hard") -> 1 | U39: =COUNTIFS(Prerequisites[Run ID], $B39, Prerequisites[Type], "hard", Prerequisites[Satisfied], TRUE) -> 0 | V39: =T39-U39 -> 1 | W39: =COUNTIFS(Prerequisites[Run ID], $B39, Prerequisites[Type], "soft") -> 2 | X39: =COUNTIFS(Prerequisites[Run ID], $B39, Prerequisites[Type], "soft", Prerequisites[Satisfied], TRUE) -> 0 | Y39: =W39-X39 -> 2 | Z39: =COUNTIFS(Prerequisites[Prereq Run ID],$B39,Prerequisites[Type], "hard") -> 0 | AA39: =COUNTIFS(Reading_Order[Run ID], $B39, Reading_Order[Completed], TRUE) -> 0 | AB39: =$G39-$AA39 -> 76 | AC39: =AA39/(AB39+AA39) -> 0 | AD39: =IF(T39<1, TRUE, FALSE) -> FALSE
A40: Captain America Origin | B40: cap-origin | C40: Captain America | D40: Joe Simon, Stan Lee, Jack Kirby | F40: Captain America Comics #1; Avengers #4; Tales of Suspense #63, 72-81; Sgt. Fury #13; Captain America #110-111, 113 | G40: =COUNTIF(Reading_Order[Run ID], B40) -> 41 | H40: 1941 | I40: 1965 | J40: =$G40>0 -> TRUE | K40: =IF($G40=0,"—",IF($AA40=$G40,"read",IF($AA40>0,"reading","unread"))) -> unread | L40: 4 | M40: Avengers #4 is the real start of modern Cap | O40: 1 | P40: 1 | Q40: FALSE | S40: =IF($V40>0, "blocked", IF($Y40=0, "ready-all", "ready-hard")) -> ready-all | T40: =COUNTIFS(Prerequisites[Run ID], $B40, Prerequisites[Type], "hard") -> 0 | U40: =COUNTIFS(Prerequisites[Run ID], $B40, Prerequisites[Type], "hard", Prerequisites[Satisfied], TRUE) -> 0 | V40: =T40-U40 -> 0 | W40: =COUNTIFS(Prerequisites[Run ID], $B40, Prerequisites[Type], "soft") -> 0 | X40: =COUNTIFS(Prerequisites[Run ID], $B40, Prerequisites[Type], "soft", Prerequisites[Satisfied], TRUE) -> 0 | Y40: =W40-X40 -> 0 | Z40: =COUNTIFS(Prerequisites[Prereq Run ID],$B40,Prerequisites[Type], "hard") -> 2 | AA40: =COUNTIFS(Reading_Order[Run ID], $B40, Reading_Order[Completed], TRUE) -> 0 | AB40: =$G40-$AA40 -> 41 | AC40: =AA40/(AB40+AA40) -> 0 | AD40: =IF(T40<1, TRUE, FALSE) -> TRUE
A41: Englehart's Captain America | B41: englehart-cap | C41: Captain America | D41: Steve Englehart | E41: Sal Buscema | F41: Captain America #153-186 | G41: =COUNTIF(Reading_Order[Run ID], B41) -> 39 | H41: 1972 | I41: 1975 | J41: =$G41>0 -> TRUE | K41: =IF($G41=0,"—",IF($AA41=$G41,"read",IF($AA41>0,"reading","unread"))) -> unread | L41: 4 | M41: Cap quits over Watergate. Still startling | O41: 1 | P41: 2 | Q41: FALSE | S41: =IF($V41>0, "blocked", IF($Y41=0, "ready-all", "ready-hard")) -> blocked | T41: =COUNTIFS(Prerequisites[Run ID], $B41, Prerequisites[Type], "hard") -> 1 | U41: =COUNTIFS(Prerequisites[Run ID], $B41, Prerequisites[Type], "hard", Prerequisites[Satisfied], TRUE) -> 0 | V41: =T41-U41 -> 1 | W41: =COUNTIFS(Prerequisites[Run ID], $B41, Prerequisites[Type], "soft") -> 1 | X41: =COUNTIFS(Prerequisites[Run ID], $B41, Prerequisites[Type], "soft", Prerequisites[Satisfied], TRUE) -> 0 | Y41: =W41-X41 -> 1 | Z41: =COUNTIFS(Prerequisites[Prereq Run ID],$B41,Prerequisites[Type], "hard") -> 1 | AA41: =COUNTIFS(Reading_Order[Run ID], $B41, Reading_Order[Completed], TRUE) -> 0 | AB41: =$G41-$AA41 -> 39 | AC41: =AA41/(AB41+AA41) -> 0 | AD41: =IF(T41<1, TRUE, FALSE) -> FALSE
A42: Kirby's Captain America | B42: kirby-cap | C42: Captain America | D42: Jack Kirby | F42: Captain America (1968) #193-214 | G42: =COUNTIF(Reading_Order[Run ID], B42) -> 25 | H42: 1976 | I42: 1977 | J42: =$G42>0 -> TRUE | K42: =IF($G42=0,"—",IF($AA42=$G42,"read",IF($AA42>0,"reading","unread"))) -> unread | L42: 4 | M42: Deranged in the best way — the Madbomb | O42: 1 | P42: 3 | Q42: FALSE | S42: =IF($V42>0, "blocked", IF($Y42=0, "ready-all", "ready-hard")) -> blocked | T42: =COUNTIFS(Prerequisites[Run ID], $B42, Prerequisites[Type], "hard") -> 1 | U42: =COUNTIFS(Prerequisites[Run ID], $B42, Prerequisites[Type], "hard", Prerequisites[Satisfied], TRUE) -> 0 | V42: =T42-U42 -> 1 | W42: =COUNTIFS(Prerequisites[Run ID], $B42, Prerequisites[Type], "soft") -> 0 | X42: =COUNTIFS(Prerequisites[Run ID], $B42, Prerequisites[Type], "soft", Prerequisites[Satisfied], TRUE) -> 0 | Y42: =W42-X42 -> 0 | Z42: =COUNTIFS(Prerequisites[Prereq Run ID],$B42,Prerequisites[Type], "hard") -> 1 | AA42: =COUNTIFS(Reading_Order[Run ID], $B42, Reading_Order[Completed], TRUE) -> 0 | AB42: =$G42-$AA42 -> 25 | AC42: =AA42/(AB42+AA42) -> 0 | AD42: =IF(T42<1, TRUE, FALSE) -> FALSE
